Workbook
Name ren_cac: Rendimiento!$B$61:$S$61
Name ren_clientes_break_even: Rendimiento!$B$65:$S$65
Name ren_good_clients: Rendimiento!$B$17:$S$17
Name ren_arpu: Rendimiento!$B$55:$S$55
Name irpf_tipos: Rangos!$B$5:$K$5
Name ren_coste_variable_por_cliente: Rendimiento!$B$54:$S$54
Name ren_margen_contribucion_porcentaje: Rendimiento!$B$57:$S$57
Name ren_payback: Rendimiento!$B$62:$S$62
Name ren_margen_contribucion: Rendimiento!$B$56:$S$56
Name ren_beneficio_neto: Rendimiento!$B$51:$S$51
Name ren_numero_clientes: Rendimiento!$B$2:$S$2
Name ren_ingreso_neto: Rendimiento!$B$41:$S$41
Name ren_margen_neto_despues_impuestos_porcentaje: Rendimiento!$B$52:$S$52
Name ren_ebitda: Rendimiento!$B$43:$S$43
Name Numero_Clientes: Rangos!$B$1:$S$1
Name ren_mrr: Rendimiento!$B$58:$S$58
Name ren_coste_variable_sms_neto: Rendimiento!$B$35:$S$35
Name costes_netos: Rendimiento!$B$42:$S$42
Name ren_cogs_neto: Rendimiento!$B$44:$S$44
Name irpf_limites: Rangos!$B$4:$K$4
Name ren_customer_adquisition: Rendimiento!$B$60:$S$60
Name ren_coste_fijo_neto: Rendimiento!$B$12
Name ren_best_clients: Rendimiento!$B$19:$S$19
Name ren_ltv_por_cac: Rendimiento!$B$64:$S$64
Name ren_margen_neto_porcentaje: Rendimiento!$B$45:$S$45
Name ren_better_clients: Rendimiento!$B$18:$S$18
Name ren_faltan_clientes_break_even: Rendimiento!$B$66:$S$66
Name ren_coste_variable_neto: Rendimiento!$B$37:$S$37
Name ren_arr: Rendimiento!$B$59:$S$59
Name ren_ltv: Rendimiento!$B$63:$S$63
Name MARGEN_CONTRIBUCION_PORCENTAJE: LAMBDA(margen_contribucion, arpu, margen_contribucion/arpu)
Name ARPU: LAMBDA(ingreso_neto, total_numero_clientes, ingreso_neto/total_numero_clientes)
Name CAC: LAMBDA(coste_adquisicion_cliente, numero_clientes, coste_adquisicion_cliente/numero_clientes)
Name MARGEN_CONTRIBUCION: LAMBDA(coste_variable_por_cliente, arpu, arpu-coste_variable_por_cliente)
Name MYCOLUMNS: LAMBDA(rango, SEQUENCE(1, COLUMNS(rango), COLUMN(rango), 1))
Name COSTO_VARIABLE_DE_INGRESO: LAMBDA(importe, total_porcentajes, (importe * total_porcentajes)/ 100)
Name POR_NUMERO_CLIENTES: LAMBDA(lambda, MAP(MYCOLUMNS(Numero_Clientes), lambda))
Name PAYBACK: LAMBDA(cac, margen_contribucion, churn_rate, (cac/margen_contribucion)*(1-churn_rate))
Name COSTE_VARIABLE_POR_TRANSACCION: LAMBDA(numero_de_transacciones, importe_por_transaccion, numero_de_transacciones * importe_por_transaccion)
Name MARGEN_NETO_PORCENTAGE: LAMBDA(ebitda, ingreso_neto, ebitda/ingreso_neto)
Name EBITDA: LAMBDA(ingreso_bruto, coste_bruto, ingreso_bruto-coste_bruto)
Name IVA: LAMBDA(bruto, bruto - (bruto / 1.21))
Name CLIENTES_BREAK_EVEN: LAMBDA(numero_clientes, margen_contribucion, numero_clientes/margen_contribucion)
Name MICELDA: LAMBDA(fila, columna, INDIRECT(ADDRESS(fila, columna, 4)))
Name NETO: LAMBDA(importe, iva, importe/1.21)
Name COSTE_VARIABLE_PARA_CUSTOMER_ADQUISITION: LAMBDA(ingreso_bruto, porcentaje_invertido, ingreso_bruto * porcentaje_invertido%)
Name FALTAN_PARA_BREAK_EVEN: LAMBDA(clientes_break_even, total_clientes, MAX(0,clientes_break_even-total_clientes))
Name COSTE_VARIABLE_POR_SMS: LAMBDA(numero_de_sms, coste_sms, coste_sms * numero_de_sms)
Name LTV_POR_CAC: LAMBDA(ltv, cac, ltv/cac)
Name IVA_A_PAGAR: LAMBDA(repercutido, soportado, repercutido - soportado)
Name POR_NAMED_RANGE: LAMBDA(named_range, lambda, MAP(MYCOLUMNS(named_range), lambda))
Name COSTE_VARIABLE_POR_CLIENTE: LAMBDA(coste_variable_neto, numero_clientes, coste_variable_neto/numero_clientes)
Name LTV: LAMBDA(margen_contribucion, permanencia_media_cliente, margen_contribucion*permanencia_media_cliente)
Name MRR: LAMBDA(ingreso_neto, churn_rate, ingreso_neto - (ingreso_neto*churn_rate%))

Sheet Rendimiento
A1: ## INPUTS
A2: Numero de clientes | B2: {=Numero_Clientes} -> 10 | C2: 25 | D2: 50 | E2: 80 | F2: 120 | G2: 170 | H2: 230 | I2: 300 | J2: 380 | K2: 470 | L2: 600 | M2: 750 | N2: 900 | O2: 1000 | P2: 1200 | Q2: 1500 | R2: 2000 | S2: 3000
A3: Good plan precio | B3: 16
A4: Better plan precio | B4: 44
A5: Best plan precio | B5: 99
A6: Good plan numero de mensajes | B6: =4*20 -> 80 | C6: Good plan precio | D6: =B3/B6 -> 0.2
A7: Better plan numero de mensajes | B7: =15*20 -> 300 | C7: Better plan precio | D7: =B4/B7 -> 0.14666667
A8: Best plan numero de mensajes | B8: =60*20 -> 1200 | C8: Best plan precio | D8: =B5/B8 -> 0.0825
A9: Distribucion good | B9: 35
A10: Distribucion better | B10: 50
A11: Distribucion best | B11: 15
A12: Total Costes Fijos Neto | B12: =POR_NUMERO_CLIENTES(LAMBDA(col, NETO(Costes_Fijos!B20, 21))) -> 3912.4311 | C12: 3912.4311 | D12: 3912.4311 | E12: 3912.4311 | F12: 3912.4311 | G12: 3912.4311 | H12: 3912.4311 | I12: 3912.4311 | J12: 3912.4311 | K12: 3912.4311 | L12: 3912.4311 | M12: 3912.4311 | N12: 3912.4311 | O12: 3912.4311 | P12: 3912.4311 | Q12: 3912.4311 | R12: 3912.4311 | S12: 3912.4311
A13: Customer stay duration | B13: 12 | C13: meses | D13: Churn rate | E13: 0.05 | F13: %
A15: ## OUTPUTS
A16: 📊 CLIENTES POR TIER
A17: Good Clients | B17: {=ROUND(Numero_Clientes*$B9%,0)} -> 4 | C17: 9 | D17: 18 | E17: 28 | F17: 42 | G17: 60 | H17: 81 | I17: 105 | J17: 133 | K17: 165 | L17: 210 | M17: 263 | N17: 315 | O17: 350 | P17: 420 | Q17: 525 | R17: 700 | S17: 1050
A18: Better Clients | B18: {=ROUND(Numero_Clientes*$B10%,0)} -> 5 | C18: 13 | D18: 25 | E18: 40 | F18: 60 | G18: 85 | H18: 115 | I18: 150 | J18: 190 | K18: 235 | L18: 300 | M18: 375 | N18: 450 | O18: 500 | P18: 600 | Q18: 750 | R18: 1000 | S18: 1500
A19: Best Clients | B19: {=ROUND(Numero_Clientes*$B11%,0)} -> 2 | C19: 4 | D19: 8 | E19: 12 | F19: 18 | G19: 26 | H19: 35 | I19: 45 | J19: 57 | K19: 71 | L19: 90 | M19: 113 | N19: 135 | O19: 150 | P19: 180 | Q19: 225 | R19: 300 | S19: 450
A20: Total Clients | B20: {=POR_NUMERO_CLIENTES(LAMBDA(col, SUM(INDEX($17:$19,,col))))} -> 11 | C20: 26 | D20: 51 | E20: 80 | F20: 120 | G20: 171 | H20: 231 | I20: 300 | J20: 380 | K20: 471 | L20: 600 | M20: 751 | N20: 900 | O20: 1000 | P20: 1200 | Q20: 1500 | R20: 2000 | S20: 3000
A21: 💰 INGRESOS MENSUALES
A22: Good Bruto | B22: =POR_NUMERO_CLIENTES(LAMBDA(col, MICELDA(17,col)* $B$3)) -> 64 | C22: 144 | D22: 288 | E22: 448 | F22: 672 | G22: 960 | H22: 1296 | I22: 1680 | J22: 2128 | K22: 2640 | L22: 3360 | M22: 4208 | N22: 5040 | O22: 5600 | P22: 6720 | Q22: 8400 | R22: 11200 | S22: 16800
A23: Better Bruto | B23: =POR_NUMERO_CLIENTES(LAMBDA(col, MICELDA(18,col)* $B$4)) -> 220 | C23: 572 | D23: 1100 | E23: 1760 | F23: 2640 | G23: 3740 | H23: 5060 | I23: 6600 | J23: 8360 | K23: 10340 | L23: 13200 | M23: 16500 | N23: 19800 | O23: 22000 | P23: 26400 | Q23: 33000 | R23: 44000 | S23: 66000
A24: Best Bruto | B24: =POR_NUMERO_CLIENTES(LAMBDA(col, MICELDA(19,col)* $B$5)) -> 198 | C24: 396 | D24: 792 | E24: 1188 | F24: 1782 | G24: 2574 | H24: 3465 | I24: 4455 | J24: 5643 | K24: 7029 | L24: 8910 | M24: 11187 | N24: 13365 | O24: 14850 | P24: 17820 | Q24: 22275 | R24: 29700 | S24: 44550
A25: Total Ingreso Bruto | B25: {=POR_NUMERO_CLIENTES(LAMBDA(col, SUM(INDEX($22:$24,,col))))} -> 482 | C25: 1112 | D25: 2180 | E25: 3396 | F25: 5094 | G25: 7274 | H25: 9821 | I25: 12735 | J25: 16131 | K25: 20009 | L25: 25470 | M25: 31895 | N25: 38205 | O25: 42450 | P25: 50940 | Q25: 63675 | R25: 84900 | S25: 127350
A26: Total Ingreso Neto | B26: =POR_NUMERO_CLIENTES( LAMBDA(col, NETO(MICELDA(25, col) , 21))) -> 398.34711 | C26: 919.00826 | D26: 1801.6529 | E26: 2806.6116 | F26: 4209.9174 | G26: 6011.5702 | H26: 8116.5289 | I26: 10524.793 | J26: 13331.405 | K26: 16536.364 | L26: 21049.587 | M26: 26359.504 | N26: 31574.38 | O26: 35082.645 | P26: 42099.174 | Q26: 52623.967 | R26: 70165.289 | S26: 105247.93
A27: 📈 DATOS PARA COSTES VARIABLES
A28: Good SMS | B28: =POR_NUMERO_CLIENTES(LAMBDA(col, MICELDA(17,col)* $B$6)) -> 320 | C28: 720 | D28: 1440 | E28: 2240 | F28: 3360 | G28: 4800 | H28: 6480 | I28: 8400 | J28: 10640 | K28: 13200 | L28: 16800 | M28: 21040 | N28: 25200 | O28: 28000 | P28: 33600 | Q28: 42000 | R28: 56000 | S28: 84000
A29: Better SMS | B29: =POR_NUMERO_CLIENTES(LAMBDA(col, MICELDA(18,col)* $B$7)) -> 1500 | C29: 3900 | D29: 7500 | E29: 12000 | F29: 18000 | G29: 25500 | H29: 34500 | I29: 45000 | J29: 57000 | K29: 70500 | L29: 90000 | M29: 112500 | N29: 135000 | O29: 150000 | P29: 180000 | Q29: 225000 | R29: 300000 | S29: 450000
A30: Best SMS | B30: =POR_NUMERO_CLIENTES(LAMBDA(col, MICELDA(19,col)* $B$8)) -> 2400 | C30: 4800 | D30: 9600 | E30: 14400 | F30: 21600 | G30: 31200 | H30: 42000 | I30: 54000 | J30: 68400 | K30: 85200 | L30: 108000 | M30: 135600 | N30: 162000 | O30: 180000 | P30: 216000 | Q30: 270000 | R30: 360000 | S30: 540000
A31: Total SMS | B31: {=POR_NUMERO_CLIENTES(LAMBDA(col, SUM(INDEX($28:$30,,col))))} -> 4220 | C31: 9420 | D31: 18540 | E31: 28640 | F31: 42960 | G31: 61500 | H31: 82980 | I31: 107400 | J31: 136040 | K31: 168900 | L31: 214800 | M31: 269140 | N31: 322200 | O31: 358000 | P31: 429600 | Q31: 537000 | R31: 716000 | S31: 1074000
A32: 📈 COSTES VARIABLES
A33: Dependiente de ingreso neto | B33: =POR_NUMERO_CLIENTES(LAMBDA(col, COSTO_VARIABLE_DE_INGRESO(MICELDA(26, col), Costes_Variables!B10))) -> 113.52893 | C33: 261.91736 | D33: 513.47107 | E33: 799.8843 | F33: 1199.8264 | G33: 1713.2975 | H33: 2313.2107 | I33: 2999.5661 | J33: 3799.4504 | K33: 4712.8636 | L33: 5999.1322 | M33: 7512.4587 | N33: 8998.6983 | O33: 9998.5537 | P33: 11998.264 | Q33: 14997.831 | R33: 19997.107 | S33: 29995.661
A34: Por transaccion | B34: =POR_NUMERO_CLIENTES(LAMBDA(col, COSTE_VARIABLE_POR_TRANSACCION(MICELDA(20, col), Costes_Variables!B13))) -> 2.75 | C34: 6.5 | D34: 12.75 | E34: 20 | F34: 30 | G34: 42.75 | H34: 57.75 | I34: 75 | J34: 95 | K34: 117.75 | L34: 150 | M34: 187.75 | N34: 225 | O34: 250 | P34: 300 | Q34: 375 | R34: 500 | S34: 750
A35: Por mensaje | B35: =POR_NUMERO_CLIENTES(LAMBDA(col, COSTE_VARIABLE_POR_SMS(MICELDA(31, col), Costes_Variables!B23))) -> 131.1998 | C35: 292.8678 | D35: 576.4086 | E35: 890.4176 | F35: 1335.6264 | G35: 1912.035 | H35: 2579.8482 | I35: 3339.066 | J35: 4229.4836 | K35: 5251.101 | L35: 6678.132 | M35: 8367.5626 | N35: 10017.198 | O35: 11130.22 | P35: 13356.264 | Q35: 16695.33 | R35: 22260.44 | S35: 33390.66
A36: Total Variables Bruto | B36: {=POR_NUMERO_CLIENTES(LAMBDA(col, SUM(INDEX($33:$35,,col))))} -> 247.47873 | C36: 561.28516 | D36: 1102.6297 | E36: 1710.3019 | F36: 2565.4528 | G36: 3668.0825 | H36: 4950.8089 | I36: 6413.6321 | J36: 8123.934 | K36: 10081.715 | L36: 12827.264 | M36: 16067.771 | N36: 19240.896 | O36: 21378.774 | P36: 25654.528 | Q36: 32068.161 | R36: 42757.547 | S36: 64136.321
A37: Total Variables Neto | B37: =POR_NUMERO_CLIENTES( LAMBDA(col, NETO(MICELDA(36, col) , 21))) -> 204.52787 | C37: 463.87203 | D37: 911.26419 | E37: 1413.4726 | F37: 2120.209 | G37: 3031.4732 | H37: 4091.5776 | I37: 5300.5224 | J37: 6713.9951 | K37: 8331.9956 | L37: 10601.045 | M37: 13279.15 | N37: 15901.567 | O37: 17668.408 | P37: 21202.09 | Q37: 26502.612 | R37: 35336.816 | S37: 53005.224
A38: "=======================" | B38: "===========" | C38: "===========" | D38: "===========" | E38: "===========" | F38: "===========" | G38: "===========" | H38: "===========" | I38: "===========" | J38: "===========" | K38: "===========" | L38: "===========" | M38: "===========" | N38: "===========" | O38: "===========" | P38: "===========" | Q38: "===========" | R38: "===========" | S38: "==========="
A39: 💵 RESUMEN FINANCIERO
A40: Ingreso Bruto | B40: =POR_NUMERO_CLIENTES( LAMBDA(col, MICELDA(25, col))) -> 482 | C40: 1112 | D40: 2180 | E40: 3396 | F40: 5094 | G40: 7274 | H40: 9821 | I40: 12735 | J40: 16131 | K40: 20009 | L40: 25470 | M40: 31895 | N40: 38205 | O40: 42450 | P40: 50940 | Q40: 63675 | R40: 84900 | S40: 127350
A41: Ingreso Neto | B41: =POR_NUMERO_CLIENTES(LAMBDA(col, MICELDA(26, col))) -> 398.34711 | C41: 919.00826 | D41: 1801.6529 | E41: 2806.6116 | F41: 4209.9174 | G41: 6011.5702 | H41: 8116.5289 | I41: 10524.793 | J41: 13331.405 | K41: 16536.364 | L41: 21049.587 | M41: 26359.504 | N41: 31574.38 | O41: 35082.645 | P41: 42099.174 | Q41: 52623.967 | R41: 70165.289 | S41: 105247.93
...

Sheet Graficas Rendimiento

Sheet Copia de Graficas Rendimiento 1

Sheet Copia de Copia de Graficas Rend

Sheet Copia de Graficas Rendimiento

Sheet Modelo numero de mensajes por t
A1: ## INPUTS
A2: Numero de clientes | B2: {=Numero_Clientes} -> 10 | C2: 25 | D2: 50 | E2: 80 | F2: 120 | G2: 170 | H2: 230 | I2: 300 | J2: 380 | K2: 470 | L2: 600 | M2: 750 | N2: 900 | O2: 1000 | P2: 1200 | Q2: 1500 | R2: 2000 | S2: 3000
A3: Good plan precio | B3: 16
A4: Better plan precio | B4: 44
A5: Best plan precio | B5: 99
A6: Distribucion clientes good | B6: 35
A7: Distribucion clientes better | B7: 50
A8: Distribucion clientes best | B8: 15
A9: Factor distribucion mensajes good | B9: =1 -> 1
A10: Factor distribucion mensajes better | B10: =3.5 -> 3.5
A11: Factor distribucion mensajes best | B11: =10 -> 10
A12: Bolsa total (** lee abajo) | B12: =(B6*B9)+(B7*B10)+(B8*B11) -> 360
A13: Total Costes Fijos (Neto) | B13: =NETO(Costes_Fijos!B20, 21) -> 3912.4311
A14: Target Margin | B14: 20
A15: ## OUTPUTS
A16: 📊 CLIENTES POR TIER
A17: Good Clients | B17: {=ROUND(Numero_Clientes*$B6%,0)} -> 4 | C17: 9 | D17: 18 | E17: 28 | F17: 42 | G17: 60 | H17: 81 | I17: 105 | J17: 133 | K17: 165 | L17: 210 | M17: 263 | N17: 315 | O17: 350 | P17: 420 | Q17: 525 | R17: 700 | S17: 1050
A18: Better Clients | B18: {=ROUND(Numero_Clientes*$B7%,0)} -> 5 | C18: 13 | D18: 25 | E18: 40 | F18: 60 | G18: 85 | H18: 115 | I18: 150 | J18: 190 | K18: 235 | L18: 300 | M18: 375 | N18: 450 | O18: 500 | P18: 600 | Q18: 750 | R18: 1000 | S18: 1500
A19: Best Clients | B19: {=ROUND(Numero_Clientes*$B8%,0)} -> 2 | C19: 4 | D19: 8 | E19: 12 | F19: 18 | G19: 26 | H19: 35 | I19: 45 | J19: 57 | K19: 71 | L19: 90 | M19: 113 | N19: 135 | O19: 150 | P19: 180 | Q19: 225 | R19: 300 | S19: 450
A20: Total Clients | B20: {=POR_NUMERO_CLIENTES(LAMBDA(col, SUM(INDEX($17:$19,,col))))} -> 11 | C20: 26 | D20: 51 | E20: 80 | F20: 120 | G20: 171 | H20: 231 | I20: 300 | J20: 380 | K20: 471 | L20: 600 | M20: 751 | N20: 900 | O20: 1000 | P20: 1200 | Q20: 1500 | R20: 2000 | S20: 3000
A21: 💰 INGRESOS MENSUALES
A22: Good Bruto | B22: =POR_NUMERO_CLIENTES(LAMBDA(col, MICELDA(17,col)* $B$3)) -> 64 | C22: 144 | D22: 288 | E22: 448 | F22: 672 | G22: 960 | H22: 1296 | I22: 1680 | J22: 2128 | K22: 2640 | L22: 3360 | M22: 4208 | N22: 5040 | O22: 5600 | P22: 6720 | Q22: 8400 | R22: 11200 | S22: 16800
A23: Better Bruto | B23: =POR_NUMERO_CLIENTES(LAMBDA(col, MICELDA(18,col)* $B$4)) -> 220 | C23: 572 | D23: 1100 | E23: 1760 | F23: 2640 | G23: 3740 | H23: 5060 | I23: 6600 | J23: 8360 | K23: 10340 | L23: 13200 | M23: 16500 | N23: 19800 | O23: 22000 | P23: 26400 | Q23: 33000 | R23: 44000 | S23: 66000
A24: Best Bruto | B24: =POR_NUMERO_CLIENTES(LAMBDA(col, MICELDA(19,col)* $B$5)) -> 198 | C24: 396 | D24: 792 | E24: 1188 | F24: 1782 | G24: 2574 | H24: 3465 | I24: 4455 | J24: 5643 | K24: 7029 | L24: 8910 | M24: 11187 | N24: 13365 | O24: 14850 | P24: 17820 | Q24: 22275 | R24: 29700 | S24: 44550
A25: Total Ingresos Bruto | B25: {=POR_NUMERO_CLIENTES(LAMBDA(col, SUM(INDEX($22:$24,,col))))} -> 482 | C25: 1112 | D25: 2180 | E25: 3396 | F25: 5094 | G25: 7274 | H25: 9821 | I25: 12735 | J25: 16131 | K25: 20009 | L25: 25470 | M25: 31895 | N25: 38205 | O25: 42450 | P25: 50940 | Q25: 63675 | R25: 84900 | S25: 127350
A26: Total Ingresos Neto | B26: =POR_NUMERO_CLIENTES( LAMBDA(col, NETO(MICELDA(25, col) , 21))) -> 398.34711 | C26: 919.00826 | D26: 1801.6529 | E26: 2806.6116 | F26: 4209.9174 | G26: 6011.5702 | H26: 8116.5289 | I26: 10524.793 | J26: 13331.405 | K26: 16536.364 | L26: 21049.587 | M26: 26359.504 | N26: 31574.38 | O26: 35082.645 | P26: 42099.174 | Q26: 52623.967 | R26: 70165.289 | S26: 105247.93
A27: 📈 COSTES VARIABLES
A28: Total dependiente de ingreso | B28: =POR_NUMERO_CLIENTES(LAMBDA(col, COSTO_VARIABLE_DE_INGRESO(MICELDA(26, col), Costes_Variables!$B10))) -> 113.52893 | C28: 261.91736 | D28: 513.47107 | E28: 799.8843 | F28: 1199.8264 | G28: 1713.2975 | H28: 2313.2107 | I28: 2999.5661 | J28: 3799.4504 | K28: 4712.8636 | L28: 5999.1322 | M28: 7512.4587 | N28: 8998.6983 | O28: 9998.5537 | P28: 11998.264 | Q28: 14997.831 | R28: 19997.107 | S28: 29995.661
A29: Total por transaccion | B29: {=POR_NUMERO_CLIENTES(LAMBDA(col, COSTE_VARIABLE_POR_TRANSACCION(INDEX($20:$20,, col), Costes_Variables!$B$13)))} -> 2.75 | C29: 6.5 | D29: 12.75 | E29: 20 | F29: 30 | G29: 42.75 | H29: 57.75 | I29: 75 | J29: 95 | K29: 117.75 | L29: 150 | M29: 187.75 | N29: 225 | O29: 250 | P29: 300 | Q29: 375 | R29: 500 | S29: 750
A30: Total Costes Variables | B30: {=POR_NUMERO_CLIENTES(LAMBDA(col, SUM(INDEX($28:$29,,col))))} -> 116.27893 | C30: 268.41736 | D30: 526.22107 | E30: 819.8843 | F30: 1229.8264 | G30: 1756.0475 | H30: 2370.9607 | I30: 3074.5661 | J30: 3894.4504 | K30: 4830.6136 | L30: 6149.1322 | M30: 7700.2087 | N30: 9223.6983 | O30: 10248.554 | P30: 12298.264 | Q30: 15372.831 | R30: 20497.107 | S30: 30745.661
A31: ## RESULTADO
A32: Total mensajes | B32: =POR_NUMERO_CLIENTES(LAMBDA(col, (MICELDA(26, col) * (1 - $B$14/100) - $B$13 - MICELDA(30, col))/Costes_Variables!$B23)) -> -119332.02 | C32: -110827.98 | D32: -96408.166 | E32: -79994.409 | F32: -57070.559 | G32: -27636.618 | H32: 6749.1562 | I32: 46086.763 | J32: 91934.462 | K32: 144292.25 | L32: 218015.63 | M32: 304759.2 | N32: 389944.5 | O32: 447254.13 | P32: 561873.38 | Q32: 733802.25 | R32: 1020350.4 | S32: 1593446.6
A33: Es posible ? | B33: =POR_NUMERO_CLIENTES(LAMBDA(col, IF(MICELDA(32, col) > 0, "🟢 Puedes enviar " & ROUND(MICELDA(32, col), 2) & " mensajes en total entre todos los clientes de todos los planes", "🔴 Te faltan " & (MICELDA(32, col) * Costes_Variables!$B23) & " Euros antes de poder enviar el primer recordatorio. Imposible, matematicamente no se puede."))) -> 🔴 Te faltan -3710,03236914601 Euros antes de poder enviar el primer recordatorio. Imposible, matematicamente no se puede. | C33: 🔴 Te faltan -3445,64187327824 Euros antes de poder enviar el primer recordatorio. Imposible, matematicamente no se puede. | D33: 🔴 Te faltan -2997,32988980716 Euros antes de poder enviar el primer recordatorio. Imposible, matematicamente no se puede. | E33: 🔴 Te faltan -2487,0261707989 Euros antes de poder enviar el primer recordatorio. Imposible, matematicamente no se puede. | F33: 🔴 Te faltan -1774,32369146006 Euros antes de poder enviar el primer recordatorio. Imposible, matematicamente no se puede. | G33: 🔴 Te faltan -859,222451790634 Euros antes de poder enviar el primer recordatorio. Imposible, matematicamente no se puede. | H33: 🟢 Puedes enviar 6749,16 mensajes en total entre todos los clientes de todos los planes | I33: 🟢 Puedes enviar 46086,76 mensajes en total entre todos los clientes de todos los planes | J33: 🟢 Puedes enviar 91934,46 mensajes en total entre todos los clientes de todos los planes | K33: 🟢 Puedes enviar 144292,25 mensajes en total entre todos los clientes de todos los planes | L33: 🟢 Puedes enviar 218015,63 mensajes en total entre todos los clientes de todos los planes | M33: 🟢 Puedes enviar 304759,2 mensajes en total entre todos los clientes de todos los planes | N33: 🟢 Puedes enviar 389944,5 mensajes en total entre todos los clientes de todos los planes | O33: 🟢 Puedes enviar 447254,13 mensajes en total entre todos los clientes de todos los planes | P33: 🟢 Puedes enviar 561873,38 mensajes en total entre todos los clientes de todos los planes | Q33: 🟢 Puedes enviar 733802,25 mensajes en total entre todos los clientes de todos los planes | R33: 🟢 Puedes enviar 1020350,36 mensajes en total entre todos los clientes de todos los planes | S33: 🟢 Puedes enviar 1593446,6 mensajes en total entre todos los clientes de todos los planes
A34: Base | B34: =POR_NUMERO_CLIENTES(LAMBDA(col, MICELDA(32, col)/$B$12)) -> -331.47782 | C34: -307.8555 | D34: -267.80046 | E34: -222.20669 | F34: -158.52933 | G34: -76.768383 | H34: 18.747656 | I34: 128.01879 | J34: 255.37351 | K34: 400.81181 | L34: 605.59898 | M34: 846.55333 | N34: 1083.1792 | O34: 1242.3726 | P34: 1560.7594 | Q34: 2038.3396 | R34: 2834.3066 | S34: 4426.2406
A35: Distribuidos por tier - good | B35: =POR_NUMERO_CLIENTES(LAMBDA(col, IF(MICELDA(34, col) > 0, MICELDA(34, col) * ($B$6*$B$9), "Que no se puede hostias"))) -> Que no se puede hostias | C35: Que no se puede hostias | D35: Que no se puede hostias | E35: Que no se puede hostias | F35: Que no se puede hostias | G35: Que no se puede hostias | H35: 656.16797 | I35: 4480.6575 | J35: 8938.0727 | K35: 14028.413 | L35: 21195.964 | M35: 29629.367 | N35: 37911.271 | O35: 43483.04 | P35: 54626.578 | Q35: 71341.885 | R35: 99200.73 | S35: 154918.42
A36: Distribuidos por tier - better | B36: =POR_NUMERO_CLIENTES(LAMBDA(col, IF(MICELDA(34, col) > 0, MICELDA(34, col) * ($B$7*$B$10), "Que no se puede hostias"))) -> Que no se puede hostias | C36: Que no se puede hostias | D36: Que no se puede hostias | E36: Que no se puede hostias | F36: Que no se puede hostias | G36: Que no se puede hostias | H36: 3280.8398 | I36: 22403.288 | J36: 44690.363 | K36: 70142.067 | L36: 105979.82 | M36: 148146.83 | N36: 189556.36 | O36: 217415.2 | P36: 273132.89 | Q36: 356709.43 | R36: 496003.65 | S36: 774592.1
A37: Distribuidos por tier - best | B37: =POR_NUMERO_CLIENTES(LAMBDA(col, IF(MICELDA(34, col) > 0, MICELDA(34, col) * ($B$8*$B$11), "Que no se puede hostias"))) -> Que no se puede hostias | C37: Que no se puede hostias | D37: Que no se puede hostias | E37: Que no se puede hostias | F37: Que no se puede hostias | G37: Que no se puede hostias | H37: 2812.1484 | I37: 19202.818 | J37: 38306.026 | K37: 60121.772 | L37: 90839.847 | M37: 126983 | N37: 162476.88 | O37: 186355.89 | P37: 234113.91 | Q37: 305750.94 | R37: 425145.99 | S37: 663936.08
A38: Good plan numero de mensajes | B38: =POR_NUMERO_CLIENTES(LAMBDA(col, IFERROR(MICELDA(35, col)/MICELDA(17, col),""))) | H38: 8.1008391 | I38: 42.672929 | J38: 67.203554 | K38: 85.020688 | L38: 100.93316 | M38: 112.65919 | N38: 120.35324 | O38: 124.23726 | P38: 130.06328 | Q38: 135.8893 | R38: 141.71533 | S38: 147.54135
A39: Better plan numero de mensajes | B39: =POR_NUMERO_CLIENTES(LAMBDA(col, IFERROR(MICELDA(36, col)/MICELDA(18, col),""))) | H39: 28.529042 | I39: 149.35525 | J39: 235.21244 | K39: 298.47688 | L39: 353.26607 | M39: 395.05822 | N39: 421.23635 | O39: 434.8304 | P39: 455.22148 | Q39: 475.61257 | R39: 496.00365 | S39: 516.39473
A40: Best plan numero de mensajes | B40: =POR_NUMERO_CLIENTES(LAMBDA(col, IFERROR(MICELDA(37, col)/MICELDA(19, col),""))) | H40: 80.347098 | I40: 426.72929 | J40: 672.03554 | K40: 846.78552 | L40: 1009.3316 | M40: 1123.7434 | N40: 1203.5324 | O40: 1242.3726 | P40: 1300.6328 | Q40: 1358.893 | R40: 1417.1533 | S40: 1475.4135
...

Sheet Costes_Variables
A1: 📈 COSTES VARIABLES | C1: Notas
A2: Dependiente de ingreso %
A3: Stripe | B3: 1.5 | C3: Esto se deberia de calcular contra el bruto, al contrario que lo demas
A4: Infraestructura | B4: 10
A5: Marketing | B5: 5
A6: Safety Margin | B6: 7
A9: Total para Customer Adquisition | B9: =B5 -> 5
A10: Total | B10: =SUM(B3:B9) -> 28.5
A11: Total para COGS | B11: =B10-B5 -> 23.5
A12: Dependiente de numero de transacciones
A13: Stripe Fixed | B13: 0.25 | C13: Esto se deberia de calcular contra el bruto, al contrario que lo demas
A20: Total | B20: =SUM(B13:B19) -> 0.25
A22: Dependiente del numero de mensajes
A23: SMS Cost a Espana (Neto) | B23: 0.03109

Sheet Rangos
A1: Numero de clientes | B1: 10 | C1: 25 | D1: 50 | E1: 80 | F1: 120 | G1: 170 | H1: 230 | I1: 300 | J1: 380 | K1: 470 | L1: 600 | M1: 750 | N1: 900 | O1: 1000 | P1: 1200 | Q1: 1500 | R1: 2000 | S1: 3000
A3: IRPF
A4: Limites | B4: 12450 | C4: 13362 | D4: 19004 | E4: 20200 | F4: 35200 | G4: 35425 | H4: 57320 | I4: 60000 | J4: 300000 | K4: 10000000
A5: Tipos | B5: 0.18 | C5: 0.205 | D5: 0.227 | E5: 0.248 | F5: 0.278 | G5: 0.313 | H5: 0.359 | I5: 0.39 | J5: 0.43 | K5: 0.45
A6: https://taxdown.es/irpf/tabla-tramos/
A12: 50 | B12: 100
A13: =A12*2 -> 100 | B13: =B12*2 -> 200 | C13: =C12*2 -> 0 | D13: =D12*2 -> 0 | E13: =E12*2 -> 0 | F13: =F12*2 -> 0 | G13: =G12*2 -> 0 | H13: =H12*2 -> 0 | ... L13: =L12*2 -> 0

Sheet Costes_Fijos
A1: 📉 COSTES FIJOS MENSUALES | B1: Importe | C1: Cuantia | D1: Divisor | E1: Frecuencia | F1: Notas
A2: Social Security | B2: =C2/D2 -> 500 | C2: =500 -> 500 | D2: 1 | E2: Mensual | F2: 2 fundadores
A3: Gestoria | B3: =C3/D3 -> 100 | C3: =100 -> 100 | D3: 1 | E3: Mensual | F3: Impuestos y tramites
A4: AI Tools | B4: =C4/D4 -> 50 | C4: =50 -> 50 | D4: 1 | E4: Mensual | F4: Herramientas IA
A5: Software contabilidad o similar | B5: =C5/D5 -> 50 | C5: =50 -> 50 | D5: 1 | E5: Mensual | F5: Maybe?
A6: Password Manager | B6: =C6/D6 -> 3.3333333 | C6: =40 -> 40 | D6: 12 | E6: Anual | F6: Herramienta seguridad
A7: Dominios | B7: =C7/D7 -> 2.7083333 | C7: =65 -> 65 | D7: 24 | E7: Bienal | F7: notifycal.es + notifycal.com
A8: Mailgun | B8: =C8/D8 -> 10 | C8: 10 | D8: 1 | E8: Mensual | F8: No es fijo pero al ser negligible para simplificar...
A9: GitHub team | B9: =C9/D9 -> 8 | C9: 8 | D9: 1 | E9: Mensual
A10: GitHub Actions extra minutes | B10: =C10/D10 -> 10 | C10: 10 | D10: 1 | E10: Mensual
A11: Sueldo 1 | B11: =2000 -> 2000
A12: Sueldo 2 | B12: =2000 -> 2000
A20: TOTAL menual | B20: =SUM(B2:B19) -> 4734.0417
